Workbook
Name \aq: #REF!
Name \c: #REF!
Name \e: #REF!
Name \f: #REF!
Name \l: #REF!
Name \p: #REF!
Name \q: #REF!
Name \s: '[1]Originating Station'!#REF!
Name \u: '[1]Originating Station'!#REF!
Name \w: #REF!
Name \x: #REF!
Name \y: '[2]SCADA(MCC-SCC)-Koyali'!#REF!
Name \z: #N/A
Name ____dim4: "$#REF!.$#REF!$#REF!"
Name ____rm4: "$#REF!.$#REF!$#REF!"
Name ___dim4: #REF!
Name ___rm4: #REF!
Name __A1: #REF!
Name __a2: #REF!
Name __a3: #REF!
Name __dim4: "$#REF!.$#REF!$#REF!"
Name __JL91: #N/A
Name __rim4: #REF!
Name __rm4: "$#REF!.$#REF!$#REF!"
Name __xlnm._FilterDatabase: "$#REF!.$B$1:$X$18"
Name _192.168.50.66: #REF!
Name _192.168.50.66: #REF!
Name _192.168.50.66: #REF!
Name _192.168.50.66: #REF!
Name _88: #N/A
Name _A1: #REF!
Name _a2: #REF!
Name _a3: #REF!
Name _dim4: #REF!
Name _EMC2: #REF!
Name _H264: #REF!
Name _H264FACTOR: #REF!
Name _HRP1001: #REF!
Name _HRP1001: #REF!
Name _HRP1001: #REF!
Name _HRP1001: #REF!
Name _HRP1023: #REF!
Name _HRP1023: #REF!
Name _HRP1023: #REF!
Name _HRP1023: #REF!
Name _HRP1025: #REF!
Name _HRP1026: #REF!
Name _HRP1027: #REF!
Name _HRP1028: #REF!
Name _HRP1035: #REF!
Name _HRP1038: #REF!
Name _HRP1042: #REF!
Name _HRT1035: #REF!
Name _HRT1042: #REF!
Name _JL91: #N/A
Name _MJPEG: #REF!
Name _MJPEGFACTOR: #REF!
Name _MPEG4: #REF!
Name _MPEG4FACTOR: #REF!
Name _Order1: 255

Sheet Summary
A1: =F10-F23 -> -7635914.6 | G1: Date | H1: 45728
C3: MRSAC Internal
B5: DC
B6: Service Components | C6: Monthly Service Pay | D6: Months | E6: Total Cost for 1 Year | F6: One Time Service Pay
B7: ESDS' eNlight Cloud Hosting Services- DC Site | C7: ='ESDS DC'!F48 -> 331049.4 | D7: 5 | E7: =C7*D7 -> 1655247 | F7: ='ESDS DC'!G48 -> 0
B8: ESDS' eNlight Cloud Hosting Services- DR Site A | D8: 1 | E8: =C8*D8 -> 0
B9: Total | E9: =SUM(E7:E8) -> 1655247 | F9: =SUM(F7:F8) -> 0
B10: Total Cost for DC Only for 12 months (Rupees twenty lakhs eighty six thousand six hundred ninety only) Excluding Taxes | F10: =E9+F9 -> 1655247
B12: DC NON HA
B13: Service Components | C13: Monthly Service Pay | D13: Months | E13: Total Cost for 1 Year | F13: One Time Service Pay
B14: ESDS' eNlight Cloud Hosting Services- DC Site | C14: ='ESDS DC NON HA'!F43 -> #REF! | D14: 12 | E14: =C14*D14 -> #REF! | F14: ='ESDS DC'!G54 -> 0
B15: Total | E15: =SUM(E14:E14) -> #REF! | F15: =SUM(F14:F14) -> 0
B17: Total Cost for DC Site (Exclusive of Taxes) | F17: =E15+F15 -> #REF!
F23: 9291161.6
B25: Terms and Condition:
B26: *All Terms & Conditions will be applicable as per Ref.no.MRSAC/Renewal/IT Cloud/62/2023
B27: Database License provisioning and its Management will be under Client Scope

Sheet ESDS DC
R1: vCores | S1: =U14 -> 0
R2: RAM | S2: =V14 -> 0 | T2: pack | U2: Additonal | W2: Total
R3: SSD | S3: =W14 -> 1600 | T3: =SUM(S10:S13) -> 400 | U3: 500 | W3: =SUM(S3:V3) -> 2500
R4: SSD | S4: =W15 -> 0
B6: eNlight Government Community Cloud Hosting Services | J6: Requirement
B7: Hosting Components | L7: ='MRSAC Rate Card'!E106 -> 4.4 | Q7: PACKS | U7: REMAINING
B8: A.1 | C8: eNlight Cloud Hosting | D8: Unit | E8: Cost/Unit | F8: MRC | G8: OTC | H8: Comment | J8: vCores | K8: RAM | L8: SSD | M8: OS | N8: DB | Q8: vCores | R8: RAM | S8: SSD | U8: vCores | V8: RAM | W8: SSD
J9: No | K9: GB | L9: GB | Q9: No | R9: GB | S9: GB | U9: No | V9: GB | W9: GB
B10: ='Server Sizing'!C8 -> Web server (IIS) + Web adaptor | C10: ='MRSAC Rate Card'!H35 -> L6 Plan: 32 vCPU 64 GB RAM 100 GB HDD 1000 IOPS, 100 GB data transfer / Month, OS: Linux OS with 1 Public IPV6 address | D10: 1 | E10: ='MRSAC Rate Card'!J35 -> 14604.7 | F10: =D10*E10 -> 14604.7 | G10: 0 | H10: Mobile Application | I10: L6 | J10: 32 | K10: 64 | L10: 500 | M10: Win Standard | O10: =D10*J10 -> 32 | Q10: 32 | R10: 64 | S10: 100 | U10: =(J10-Q10)*$D10 -> 0 | V10: =(K10-R10)*$D10 -> 0 | W10: =(L10-S10)*$D10 -> 400 | Y10: =L10*D10 -> 500
B11: Web server (Tomcat) | C11: ='MRSAC Rate Card'!H35 -> L6 Plan: 32 vCPU 64 GB RAM 100 GB HDD 1000 IOPS, 100 GB data transfer / Month, OS: Linux OS with 1 Public IPV6 address | D11: 1 | E11: ='MRSAC Rate Card'!J35 -> 14604.7 | F11: =D11*E11 -> 14604.7 | G11: 0 | H11: Mobile Application | I11: L6 | J11: 32 | K11: 64 | L11: 500 | M11: Win Standard | O11: =D11*J11 -> 32 | Q11: 32 | R11: 64 | S11: 100 | U11: =(J11-Q11)*$D11 -> 0 | V11: =(K11-R11)*$D11 -> 0 | W11: =(L11-S11)*$D11 -> 400 | Y11: =L11*D11 -> 500
B12: Application server (GIS) + Web adaptor | C12: ='MRSAC Rate Card'!H35 -> L6 Plan: 32 vCPU 64 GB RAM 100 GB HDD 1000 IOPS, 100 GB data transfer / Month, OS: Linux OS with 1 Public IPV6 address | D12: 1 | E12: ='MRSAC Rate Card'!E35 -> 31193.8 | F12: =D12*E12 -> 31193.8 | G12: 0 | H12: Mobile Application | I12: L6 | J12: 32 | K12: 64 | L12: 500 | M12: Win Standard | O12: =D12*J12 -> 32 | Q12: 32 | R12: 64 | S12: 100 | U12: =(J12-Q12)*$D12 -> 0 | V12: =(K12-R12)*$D12 -> 0 | W12: =(L12-S12)*$D12 -> 400 | Y12: =L12*D12 -> 500
B13: Database server | C13: ='MRSAC Rate Card'!H36 -> L7 Plan: 32 vCPU 128 GB RAM 100 GB HDD 1000 IOPS, 100 GB data transfer / Month, OS: Linux OS with 1 Public IPV6 address | D13: 1 | E13: ='MRSAC Rate Card'!J36 -> 21498.4 | F13: =D13*E13 -> 21498.4 | G13: 0 | H13: Mobile Application Database | I13: L7 | J13: 32 | K13: 128 | L13: 500 | M13: Win Standard | N13: Postgres SQL | O13: =D13*J13 -> 32 | Q13: 32 | R13: 128 | S13: 100 | U13: =(J13-Q13)*$D13 -> 0 | V13: =(K13-R13)*$D13 -> 0 | W13: =(L13-S13)*$D13 -> 400 | Y13: =L13*D13 -> 500
J14: =SUM(J10:J13) -> 128 | K14: =SUM(K10:K13) -> 320 | L14: =SUM(L10:L13) -> 2000 | Q14: =SUM(Q10:Q13) -> 128 | R14: =SUM(R10:R13) -> 320 | S14: =SUM(S10:S13) -> 400 | U14: =SUM(U10:U13) -> 0 | V14: =SUM(V10:V13) -> 0 | W14: =SUM(W10:W13) -> 1600
C15: Software Licenses | D15: Unit | E15: Cost/Unit | F15: MRC | G15: OTC | H15: Comment
B16: OS | C16: ='MRSAC Rate Card'!C56 -> OS :Windows 2019 or Latest std Edition per 2 core lic | D16: =SUMIFS(O10:O13,M10:M13,M10)/2 -> 64 | E16: ='MRSAC Rate Card'!E56 -> 583 | F16: =D16*E16 -> 37312 | G16: 0 | H16: As per Sizing
B17: DB | C17: ='MRSAC Rate Card'!C70 -> PostgreSQL Community Edition Latest (Free Version)- Per Instance | D17: ='MRSAC Rate Card'!$E$70 -> Community Edition | E17: ='MRSAC Rate Card'!$E$70 -> Community Edition | F17: ='MRSAC Rate Card'!$E$70 -> Community Edition | G17: ='MRSAC Rate Card'!$E$70 -> Community Edition | H17: Community Edition - Client Scope
B18: AV | C18: ='MRSAC Rate Card'!C154 -> Antivirus + HIPS | D18: =SUM(D10:D13) -> 4 | E18: ='MRSAC Rate Card'!E154 -> 1346.4 | F18: =D18*E18 -> 5385.6 | G18: 0 | H18: As per Sizing
B20: A.3 | C20: Additonal Compute & Storage | D20: Unit | E20: Cost/Unit | F20: MRC | G20: OTC | H20: Comment
B21: Additonal Compute & Storage | C21: Additional vCore | D21: =S1 -> 0 | E21: ='MRSAC Rate Card'!E52 -> 140.8 | F21: =D21*E21 -> 0 | G21: 0 | H21: As Per inputs
C22: Additional Ram | D22: =S2 -> 0 | E22: ='MRSAC Rate Card'!E55 -> 234.3 | F22: =D22*E22 -> 0 | G22: 0 | H22: As Per inputs
C23: Additional Storage ( 100 GB Pack ) | D23: =W14/100 -> 16 | E23: ='MRSAC Rate Card'!E100 -> 707.3 | F23: =D23*E23 -> 11316.8 | G23: 0 | H23: As Per inputs
C24: ='MRSAC Rate Card'!C101 -> 500 GB Storage on SSD with IOPS 3000/TB | D24: 1 | E24: ='MRSAC Rate Card'!E101 -> 4039.2 | F24: =D24*E24 -> 4039.2 | G24: 0 | H24: As Per inputs
C25: Backup Storage ( 500 GB ) | D25: =ROUNDUP((W3*1.75/500),0) -> 9 | E25: ='MRSAC Rate Card'!E120 -> 3366 | F25: =D25*E25 -> 30294 | G25: 0 | H25: As Per inputs
B27: A.4 | C27: Network/ Connectivity | D27: Unit | E27: Cost/Unit | F27: MRC | G27: OTC | H27: Comment
B28: Service | C28: ='MRSAC Rate Card'!C177 -> Speed Based-Internet Bandwidth - Connectivity- 1 Mbps | D28: Existing | E28: Existing | F28: Existing | G28: Existing
B29: Service | C29: ='MRSAC Rate Card'!C171 -> CITRIX - Virtual Load Balancer - 1 Gbps | D29: Existing | E29: Existing | F29: Existing | G29: Existing
B30: Service | C30: ='MRSAC Rate Card'!C173 -> IPv4- Public IP - Internal Network | D30: Included | E30: Included | F30: Included | H30: As Per inputs
B32: A.5 | C32: Security | D32: Unit | E32: Cost/Unit | F32: MRC | G32: OTC | H32: Comment
C33: ='MRSAC Rate Card'!C152 -> vUTM 1 Gbps throughput | D33: Existing | E33: Existing | F33: Existing | G33: Existing | H33: Existing
C34: ='SOC Services'!B24 -> VAPT Services | D34: =SUM(D10:D13,D33,D30)+12+2+2 -> 20 | E34: ='SOC Services'!E24 -> 6732 | F34: =D34*E34 -> 134640 | G34: 0 | H34: Yearly Once , and once before deployment
C35: ='MRSAC Rate Card'!C158 -> SIEM as a service - Per Instance Or Per device (up to 100 devices & 500 EPS, Log retention for 6 Months) | D35: =SUM(D10:D13,D33:D33) -> 4 | E35: ='SOC Services'!E4 -> 3594.8 | F35: =D35*E35 -> 14379.2 | G35: 0 | H35: As Per inputs
B36: A.7 | C36: Managed Hosting Services | D36: Unit | E36: Cost/Unit | F36: MRC | G36: OTC | H36: Comment
C37: ='MRSAC Rate Card'!C182 -> Operating System Management Service Per VM | D37: =D18 -> 4 | E37: ='MRSAC Rate Card'!E182 -> 1683 | F37: =D37*E37 -> 6732 | G37: 0
C38: ='MRSAC Rate Card'!C199 -> PostgresSQL Database Managed Services (Up to 100 GB) | D38: Client Scope | E38: Client Scope | F38: Client Scope | G38: Client Scope
C39: ='MRSAC Rate Card'!C184 -> Antivirus Management Service Per VM | D39: =SUM(D10:D13) -> 4 | E39: ='MRSAC Rate Card'!E184 -> 112.2 | F39: =D39*E39 -> 448.8 | G39: 0
C40: ='MRSAC Rate Card'!C205 -> Storage Management Service | D40: 1 | E40: ='MRSAC Rate Card'!E183 -> 1683 | F40: =D40*E40 -> 1683 | G40: 0
C41: ='MRSAC Rate Card'!C181 -> Backup Management Per VM | D41: =SUM(D10:D13) -> 4 | E41: ='MRSAC Rate Card'!E181 -> 336.6 | F41: =D41*E41 -> 1346.4 | G41: 0
C42: ='MRSAC Rate Card'!C210 -> Virtual Load Balancer Managed Services | D42: Existing | E42: Existing | F42: Existing | G42: Existing | H42: Existing
C43: ='MRSAC Rate Card'!C211 -> vUTM Firewall Managed Services | D43: Existing | E43: Existing | F43: Existing | G43: Existing | H43: Existing
C44: ='MRSAC Rate Card'!C81 -> Cloud Monitoring-Advance Module-Upto25 | D44: =SUM(D37,D43:D43) -> 4 | E44: ='MRSAC Rate Card'!E81 -> 392.7 | F44: =D44*E44 -> 1570.8 | G44: 0
...

Sheet ESDS DC NON HA
B6: eNlight Government Community Cloud Hosting Services | J6: Compute
B7: Hosting Components | J7: =#REF! -> #REF! | K7: =#REF! -> #REF! | L7: =#REF! -> #REF!
B8: A.1 | C8: eNlight Cloud Hosting | D8: Unit | E8: Cost/Unit | F8: MRC | G8: OTC | H8: Comment | J8: vCores | K8: RAM | L8: SSD | M8: OS | N8: DB
J9: No | K9: GB | L9: GB
B10: ='Server Sizing'!#REF! -> #REF! | C10: =CONCATENATE("vCores: ",J10," | RAM: ",K10," GB | Performance Storage (1000 IOPs/TB): ",L10," GB | OS: ",M10,"|DB: ",N10,"") -> #REF! | D10: ='Server Sizing'!#REF! -> #REF! | E10: =SUM((J$7*K10)+(K$7*J10)+(L$7*L10)) -> #REF! | F10: =D10*E10 -> #REF! | G10: 0 | J10: ='Server Sizing'!#REF! -> #REF! | K10: ='Server Sizing'!#REF! -> #REF! | L10: ='Server Sizing'!#REF! -> #REF! | M10: ='Server Sizing'!#REF! -> #REF! | N10: ='Server Sizing'!#REF! -> #REF! | O10: =D10*J10 -> #REF! | Q10: =L10*D10 -> #REF!
B11: ='Server Sizing'!#REF! -> #REF! | C11: =CONCATENATE("vCores: ",J11," | RAM: ",K11," GB | Performance Storage (1000 IOPs/TB): ",L11," GB | OS: ",M11,"|DB: ",N11,"") -> #REF! | D11: ='Server Sizing'!#REF! -> #REF! | E11: =SUM((J$7*K11)+(K$7*J11)+(L$7*L11)) -> #REF! | F11: =D11*E11 -> #REF! | G11: 0 | J11: ='Server Sizing'!#REF! -> #REF! | K11: ='Server Sizing'!#REF! -> #REF! | L11: ='Server Sizing'!#REF! -> #REF! | M11: ='Server Sizing'!#REF! -> #REF! | N11: ='Server Sizing'!#REF! -> #REF! | O11: =D11*J11 -> #REF! | Q11: =L11*D11 -> #REF!
B12: ='Server Sizing'!#REF! -> #REF! | C12: =CONCATENATE("vCores: ",J12," | RAM: ",K12," GB | Performance Storage (1000 IOPs/TB): ",L12," GB | OS: ",M12,"|DB: ",N12,"") -> #REF! | D12: ='Server Sizing'!#REF! -> #REF! | E12: =SUM((J$7*K12)+(K$7*J12)+(L$7*L12)) -> #REF! | F12: =D12*E12 -> #REF! | G12: 0 | J12: ='Server Sizing'!#REF! -> #REF! | K12: ='Server Sizing'!#REF! -> #REF! | L12: ='Server Sizing'!#REF! -> #REF! | M12: ='Server Sizing'!#REF! -> #REF! | N12: ='Server Sizing'!#REF! -> #REF! | O12: =D12*J12 -> #REF! | Q12: =L12*D12 -> #REF!
B13: ='Server Sizing'!#REF! -> #REF! | C13: =CONCATENATE("vCores: ",J13," | RAM: ",K13," GB | Performance Storage (1000 IOPs/TB): ",L13," GB | OS: ",M13,"|DB: ",N13,"") -> #REF! | D13: ='Server Sizing'!#REF! -> #REF! | E13: =SUM((J$7*K13)+(K$7*J13)+(L$7*L13)) -> #REF! | F13: =D13*E13 -> #REF! | G13: 0 | J13: ='Server Sizing'!#REF! -> #REF! | K13: ='Server Sizing'!#REF! -> #REF! | L13: ='Server Sizing'!#REF! -> #REF! | M13: ='Server Sizing'!#REF! -> #REF! | N13: ='Server Sizing'!#REF! -> #REF! | O13: =D13*J13 -> #REF! | Q13: =L13*D13 -> #REF!
B14: ='Server Sizing'!#REF! -> #REF! | C14: =CONCATENATE("vCores: ",J14," | RAM: ",K14," GB | Performance Storage (1000 IOPs/TB): ",L14," GB | OS: ",M14,"|DB: ",N14,"") -> #REF! | D14: ='Server Sizing'!#REF! -> #REF! | E14: =SUM((J$7*K14)+(K$7*J14)+(L$7*L14)) -> #REF! | F14: =D14*E14 -> #REF! | G14: 0 | J14: ='Server Sizing'!#REF! -> #REF! | K14: ='Server Sizing'!#REF! -> #REF! | L14: ='Server Sizing'!#REF! -> #REF! | M14: ='Server Sizing'!#REF! -> #REF! | N14: ='Server Sizing'!#REF! -> #REF! | O14: =D14*J14 -> #REF! | Q14: =L14*D14 -> #REF!
Q15: =SUM(Q10:Q14) -> #REF!
B16: A.2 | C16: Software Licenses | D16: Unit | E16: Cost/Unit | F16: MRC | G16: OTC | H16: Comment
B17: OS | C17: Windows Server | D17: =SUMIFS(O10:O14,M10:M14,M10)/2 -> #REF! | E17: =#REF! -> #REF! | F17: =D17*E17 -> #REF! | G17: 0 | H17: As per Sizing
B18: AV | C18: Antivirus + HIPS | D18: =SUM(D10:D14) -> #REF! | E18: =#REF! -> #REF! | F18: =D18*E18 -> #REF! | G18: 0 | H18: As per Sizing
B19: Backup Agent | C19: Backup Agent | D19: =SUM(D10:D14) -> #REF! | E19: =#REF! -> #REF! | F19: =D19*E19 -> #REF! | G19: 0 | H19: As per Sizing
B21: A.3 | C21: Additonal Compute & Storage | D21: Unit | E21: Cost/Unit | F21: MRC | G21: OTC | H21: Comment
B22: Backup Storage | C22: Backup Storage | D22: =SUM(D10:D14)*200 -> #REF! | E22: =#REF!/1000 -> #REF! | F22: =D22*E22 -> #REF! | G22: 0 | H22: As Per inputs
B24: A.4 | C24: Network/ Connectivity | D24: Unit | E24: Cost/Unit | F24: MRC | G24: OTC | H24: Comment
B25: Service | C25: Speed based unmetered internet bandwidth | D25: 10 | E25: =#REF! -> #REF! | F25: =D25*E25 -> #REF! | H25: Additional 10 Mbps considering a GIS application
C26: Public IP | D26: 4 | E26: =#REF! -> #REF! | F26: =D26*E26 -> #REF! | G26: 0 | H26: As Per inputs
B28: A.5 | C28: Security | D28: Unit | E28: Cost/Unit | F28: MRC | G28: OTC | H28: Comment
B29: Service | C29: DDoS Mitigation up to 1 Gbps Mitigation | D29: Exisitng | E29: Exisitng | F29: Exisitng | G29: Exisitng | H29: Exisitng
C30: vFirewall (vUTM) with 1 Gbps throughput | D30: Exisitng | E30: Exisitng | F30: Exisitng | G30: Exisitng | H30: Exisitng
C31: Internal vFirewall with 1 Gbps throughput | D31: Exisitng | E31: Exisitng | F31: Exisitng | G31: Exisitng | H31: Exisitng
C32: SIEM As A Service | D32: =SUM(D10:D14,D30:D31,) -> #REF! | E32: =#REF! -> #REF! | F32: =D32*E32 -> #REF! | G32: 0 | H32: As Per Meity
C33: IAM for Cloud Portal | D33: Exisitng | E33: Exisitng | F33: Exisitng | G33: Exisitng | H33: Exisitng
B34: A.7 | C34: Managed Hosting Services | D34: Unit | E34: Cost/Unit | F34: MRC | G34: OTC | H34: Comment
C35: Operating System Management Services | D35: =D18 -> #REF! | E35: =#REF! -> #REF! | F35: =D35*E35 -> #REF! | G35: 0
C36: Storage Management Service | D36: 1 | E36: =#REF! -> #REF! | F36: =D36*E36 -> #REF! | G36: 0
C37: Backup Management Services | D37: =D19 -> #REF! | E37: =#REF! -> #REF! | F37: =D37*E37 -> #REF! | G37: 0
C38: vFirewall Management Services | D38: Exisitng | E38: Exisitng | F38: Exisitng | G38: Exisitng | H38: Exisitng
C39: ESDS Basic Monitoring | D39: =SUM(D35,D38:D38) -> #REF! | E39: =#REF! -> #REF! | F39: =D39*E39 -> #REF! | G39: 0
B41: Infrastructure (A.1 + A.2 + A.3 + A.4+A.5+A.6) | F41: =SUM(F10:F33) -> #REF! | G41: =SUM(G10:G33) -> 0
B42: Managed Services (A.7) | F42: =SUM(F35:F40) -> #REF! | G42: =SUM(G35:G39) -> 0
B43: Grand Total | F43: =SUM(F41+F42) -> #REF! | G43: =SUM(G41+G42) -> 0

Sheet ESDS DR P
B6: eNlight Government Community Cloud Hosting Services | J6: Requirement
B7: Hosting Components | J7: ='ESDS DC'!J7 -> 0 | K7: ='ESDS DC'!K7 -> 0 | L7: ='MRSAC Rate Card'!E106 -> 4.4 | Q7: PACKS | U7: REMAINING
B8: A.1 | C8: eNlight Cloud Hosting | D8: Unit | E8: Cost/Unit | F8: MRC | G8: OTC | H8: Comment | J8: vCores | K8: RAM | L8: SSD | M8: OS | N8: DB | Q8: vCores | R8: RAM | S8: SSD | U8: vCores | V8: RAM | W8: SSD
J9: No | K9: GB | L9: GB | Q9: No | R9: GB | S9: GB | U9: No | V9: GB | W9: GB | Y9: =L10*D10 -> #REF!
B10: ='Server Sizing'!#REF! -> #REF! | C10: ='MRSAC Rate Card'!H36 -> L7 Plan: 32 vCPU 128 GB RAM 100 GB HDD 1000 IOPS, 100 GB data transfer / Month, OS: Linux OS with 1 Public IPV6 address | D10: ='Server Sizing'!#REF! -> #REF! | E10: =L10*$L$7 -> #REF! | F10: =D10*E10 -> #REF! | G10: 0 | H10: ArcGIS server | I10: L7 | J10: 0 | K10: 0 | L10: ='Server Sizing'!#REF! -> #REF! | M10: ='Server Sizing'!#REF! -> #REF! | N10: ='Server Sizing'!#REF! -> #REF! | O10: =D10*J10 -> #REF! | P10: L7 | Q10: 32 | R10: 128 | S10: 100 | Y10: =L11*D11 -> #REF!
B11: ='Server Sizing'!#REF! -> #REF! | C11: ='MRSAC Rate Card'!H27 -> M13 Plan: 14 vCPU 64 GB RAM 100 GB HDD 1000 IOPS, 100 GB data transfer / Month, OS: Linux OS with 1 Public IPV6 address | D11: ='Server Sizing'!#REF! -> #REF! | E11: =L11*$L$7 -> #REF! | F11: =D11*E11 -> #REF! | G11: 0 | H11: Web adapter server | I11: M13 | J11: 0 | K11: 0 | L11: ='Server Sizing'!#REF! -> #REF! | M11: ='Server Sizing'!#REF! -> #REF! | N11: ='Server Sizing'!#REF! -> #REF! | O11: =D11*J11 -> #REF! | P11: M13 | Q11: 14 | R11: 64 | S11: 100 | Y11: =L12*D12 -> #REF!
B12: ='Server Sizing'!#REF! -> #REF! | C12: ='MRSAC Rate Card'!H36 -> L7 Plan: 32 vCPU 128 GB RAM 100 GB HDD 1000 IOPS, 100 GB data transfer / Month, OS: Linux OS with 1 Public IPV6 address | D12: ='Server Sizing'!#REF! -> #REF! | E12: =#REF! -> #REF! | F12: =D12*E12 -> #REF! | G12: 0 | H12: Database server | I12: L7 | J12: ='Server Sizing'!#REF! -> #REF! | K12: ='Server Sizing'!#REF! -> #REF! | L12: ='Server Sizing'!#REF! -> #REF! | M12: ='Server Sizing'!#REF! -> #REF! | N12: ='Server Sizing'!#REF! -> #REF! | O12: =D12*J12 -> #REF! | P12: L7 | Q12: 32 | R12: 128 | S12: 100 | U12: =(J12-Q12)*$D12 -> #REF! | V12: =(K12-R12)*$D12 -> #REF! | W12: =(L12-S12)*$D12 -> #REF! | Y12: =L13*D13 -> #REF!
B13: ='Server Sizing'!#REF! -> #REF! | C13: ='MRSAC Rate Card'!H36 -> L7 Plan: 32 vCPU 128 GB RAM 100 GB HDD 1000 IOPS, 100 GB data transfer / Month, OS: Linux OS with 1 Public IPV6 address | D13: ='Server Sizing'!#REF! -> #REF! | E13: =L13*$L$7 -> #REF! | F13: =D13*E13 -> #REF! | G13: 0 | H13: IIS server | I13: L7 | J13: 0 | K13: 0 | L13: ='Server Sizing'!#REF! -> #REF! | M13: ='Server Sizing'!#REF! -> #REF! | N13: ='Server Sizing'!#REF! -> #REF! | O13: =D13*J13 -> #REF! | P13: L7 | Q13: 32 | R13: 128 | S13: 100 | Y13: =L14*D14 -> #REF!
B14: ='Server Sizing'!#REF! -> #REF! | C14: ='MRSAC Rate Card'!H36 -> L7 Plan: 32 vCPU 128 GB RAM 100 GB HDD 1000 IOPS, 100 GB data transfer / Month, OS: Linux OS with 1 Public IPV6 address | D14: ='Server Sizing'!#REF! -> #REF! | E14: =L14*$L$7 -> #REF! | F14: =D14*E14 -> #REF! | G14: 0 | H14: Tomcat Server | I14: L7 | J14: 0 | K14: 0 | L14: ='Server Sizing'!#REF! -> #REF! | M14: ='Server Sizing'!#REF! -> #REF! | N14: ='Server Sizing'!#REF! -> #REF! | O14: =D14*J14 -> #REF! | P14: L7 | Q14: 32 | R14: 128 | S14: 100 | Y14: =SUM(Y9:Y13) -> #REF!
J15: =SUM(J10:J14) -> #REF! | K15: =SUM(K10:K14) -> #REF! | L15: =SUM(L10:L14) -> #REF! | Q15: =SUM(Q10:Q14) -> 142 | R15: =SUM(R10:R14) -> 576 | S15: =SUM(S10:S14) -> 500 | U15: =SUM(U10:U14) -> #REF! | V15: =SUM(V10:V14) -> #REF! | W15: =SUM(W10:W14) -> #REF!
B16: A.2 | C16: Software Licenses | D16: Unit | E16: Cost/Unit | F16: MRC | G16: OTC | H16: Comment
B17: OS | C17: ='MRSAC Rate Card'!C56 -> OS :Windows 2019 or Latest std Edition per 2 core lic | D17: =SUMIFS(O10:O14,M10:M14,M10)/2 -> #REF! | E17: ='MRSAC Rate Card'!E56 -> 583 | F17: =D17*E17 -> #REF! | G17: 0 | H17: As per Sizing | P17: vCores | Q17: =U15 -> #REF!
B18: DB | C18: ='MRSAC Rate Card'!C70 -> PostgreSQL Community Edition Latest (Free Version)- Per Instance | D18: Freeware | E18: Freeware | F18: Freeware | G18: Freeware | H18: Freeware | P18: RAM | Q18: =V15 -> #REF!
B19: AV | C19: ='MRSAC Rate Card'!C154 -> Antivirus + HIPS | D19: =SUM(D12) -> #REF! | E19: ='MRSAC Rate Card'!E154 -> 1346.4 | F19: =D19*E19 -> #REF! | G19: 0 | H19: As per Sizing | P19: SSD | Q19: =W15 -> #REF!
B20: DRM | C20: ='MRSAC Rate Card'!C77 -> DRM Software- Per Instance (Carbonite, Sanovi & Perpetuati) | D20: =SUM(D10:D14) -> #REF! | E20: ='MRSAC Rate Card'!E77 -> 5610 | F20: =D20*E20 -> #REF! | G20: 0 | H20: As per Sizing
B22: A.3 | C22: Additonal Compute & Storage | D22: Unit | E22: Cost/Unit | F22: MRC | G22: OTC | H22: Comment
B23: Backup Storage | C23: Additional vCore | D23: =Q17 -> #REF! | E23: ='MRSAC Rate Card'!E54 -> 234.3 | F23: =D23*E23 -> #REF! | G23: 0 | H23: As Per inputs
B24: =C22 -> Additonal Compute & Storage | C24: Additional Storage ( 100 GB Pack ) | D24: =Q19/100 -> #REF! | E24: ='MRSAC Rate Card'!E100 -> 707.3 | F24: =D24*E24 -> #REF! | G24: 0 | H24: As Per inputs
C25: Object Storage - 1 TB | D25: 25 | E25: ='MRSAC Rate Card'!E108 -> 2244 | F25: =D25*E25 -> 56100 | G25: 0 | H25: As Per inputs
B27: A.4 | C27: Network/ Connectivity | D27: Unit | E27: Cost/Unit | F27: MRC | G27: OTC | H27: Comment
B28: Service | C28: ='MRSAC Rate Card'!C177 -> Speed Based-Internet Bandwidth - Connectivity- 1 Mbps | D28: 10 | E28: ='MRSAC Rate Card'!E177 -> 561 | F28: =D28*E28 -> 5610 | H28: As Per inputs
C29: Replication Link bandwidth | D29: 10 | E29: =#REF! -> #REF! | F29: =D29*E29 -> #REF! | H29: As Per inputs
C30: ='MRSAC Rate Card'!C171 -> CITRIX - Virtual Load Balancer - 1 Gbps | D30: 1 | E30: ='MRSAC Rate Card'!E171 -> 14026.1 | F30: =D30*E30 -> 14026.1 | H30: As Per inputs
B32: A.5 | C32: Security | D32: Unit | E32: Cost/Unit | F32: MRC | G32: OTC | H32: Comment
C33: ='MRSAC Rate Card'!C152 -> vUTM 1 Gbps throughput | D33: 1 | E33: ='MRSAC Rate Card'!E152 -> 14026.1 | F33: =D33*E33 -> 14026.1 | G33: 0 | H33: As Per inputs
C34: ='MRSAC Rate Card'!C158 -> SIEM as a service - Per Instance Or Per device (up to 100 devices & 500 EPS, Log retention for 6 Months) | D34: =SUM(D12,D33:D33,D30) -> #REF! | E34: ='SOC Services'!E4 -> 3594.8 | F34: =D34*E34 -> #REF! | G34: 0 | H34: As Per inputs
B35: A.7 | C35: Managed Hosting Services | D35: Unit | E35: Cost/Unit | F35: MRC | G35: OTC | H35: Comment
C36: One Time Cost | D36: 1 | E36: =(F48*12)*5% -> #REF! | G36: =E36 -> #REF!
C37: ='MRSAC Rate Card'!C182 -> Operating System Management Service Per VM | D37: =D19 -> #REF! | E37: ='MRSAC Rate Card'!E182 -> 1683 | F37: =D37*E37 -> #REF! | G37: 0
C38: ='MRSAC Rate Card'!C199 -> PostgresSQL Database Managed Services (Up to 100 GB) | D38: =D12 -> #REF! | E38: ='MRSAC Rate Card'!E199 -> 8415 | F38: =D38*E38 -> #REF! | G38: 0
C39: ='MRSAC Rate Card'!C205 -> Storage Management Service | D39: 1 | E39: ='MRSAC Rate Card'!E183 -> 1683 | F39: =D39*E39 -> 1683 | G39: 0
C40: ='MRSAC Rate Card'!C185 -> DR Drill (Per Application) | D40: =SUM(D10:D14) -> #REF! | E40: ='MRSAC Rate Card'!E185 -> 6171 | F40: =D40*E40 -> #REF! | G40: 0 | H40: Yearly Once
C41: ='MRSAC Rate Card'!C200 -> Replication Managed Services | D41: =SUM(D10:D14) -> #REF! | E41: ='MRSAC Rate Card'!E200 -> 1683 | F41: =D41*E41 -> #REF! | G41: 0
C42: ='MRSAC Rate Card'!C211 -> vUTM Firewall Managed Services | D42: =SUM(D33:D33) -> 1 | E42: ='MRSAC Rate Card'!E211 -> 2244 | F42: =D42*E42 -> 2244 | G42: 0
C43: ='MRSAC Rate Card'!C210 -> Virtual Load Balancer Managed Services | D43: =SUM(D30) -> 1 | E43: ='MRSAC Rate Card'!E210 -> 1683 | F43: =D43*E43 -> 1683 | G43: 0
C44: ='MRSAC Rate Card'!C81 -> Cloud Monitoring-Advance Module-Upto25 | D44: =SUM(D37,D42:D43) -> #REF! | E44: ='MRSAC Rate Card'!E81 -> 392.7 | F44: =D44*E44 -> #REF! | G44: 0
B46: Infrastructure (A.1 + A.2 + A.3 + A.4+A.5+A.6) | F46: =SUM(F10:F34) -> #REF! | G46: =SUM(G10:G34) -> 0
B47: Managed Services (A.7) | F47: =SUM(F37:F45) -> #REF! | G47: =SUM(G36:G44) -> #REF!
B48: Grand Total | F48: =SUM(F46+F47) -> #REF! | G48: =SUM(G46+G47) -> #REF!

Sheet Server Sizing
B7: Sr. No. | C7: Server | D7: VM Configuration | F7: Qty
B8: 1 | C8: Web server (IIS) + Web adaptor | D8: CPU | E8: 32 Core | F8: 1
D9: RAM | E9: 64 GB
D10: HDD | E10: 500 GB
D11: OS | E11: Windows server
D12: Storage | E12: Shared storage
B13: 2 | C13: Web server (Tomcat) | D13: CPU | E13: 32 Core | F13: 1
D14: RAM | E14: 64 GB
D15: HDD | E15: 500 GB
D16: OS | E16: Windows server
D17: Storage | E17: 500 GB (As per requirement shared)
B18: 3 | C18: Application server (GIS) | D18: CPU | E18: 32 Core | F18: 1
D19: RAM | E19: 64 GB
D20: HDD | E20: 500 GB
D21: OS | E21: Windows server
D22: Storage | E22: Shared storage As per requirement
B23: 4 | C23: Database server | D23: CPU | E23: 32 Core | F23: 1
D24: RAM | E24: 128 GB
D25: HDD | E25: 500 GB
D26: OS | E26: Windows server
D27: Storage | E27: Shared storage as per requirement
B28: Total | F28: 7

Sheet MRSAC Rate Card
B1: ESDS Rate Card Transfer Price to BSNL for Cloud, SOC and Colocation Service to MRSAC
C2: 1. Unit price for Cloud Service | E2: Rate card | H2: 1. Unit price for Cloud Service | J2: Rate card
C3: VM's with 1:1 allocation | H3: VM's with 1:2 allocation
B4: SL.NO | C4: TABLE-1 : Cloud | D4: Unit of Measurement | E4: Unit price/Month | G4: SL.NO | H4: TABLE-1 : Cloud | I4: Unit of Measurement | J4: Unit price/Month
B5: 1 | C5: S1 Plan: 2vCPU 4 GB RAM 100 GB HDD 1000 IOPS, 100 GB data transfer / Month, OS: Linux OS with 1 Public IPV6 address | D5: Number | E5: 5946.6 | G5: 1 | H5: S1 Plan: 2vCPU 4 GB RAM 100 GB HDD 1000 IOPS, 100 GB data transfer / Month, OS: Linux OS with 1 Public IPV6 address | I5: Number | J5: 4910.4
B6: 2 | C6: S2 Plan: 2vCPU 8 GB RAM 100 GB HDD 1000 IOPS, 100 GB data transfer / Month, OS: Linux OS with 1 Public IPV6 address | D6: Number | E6: 7068.6 | G6: 2 | H6: S2 Plan: 2vCPU 8 GB RAM 100 GB HDD 1000 IOPS, 100 GB data transfer / Month, OS: Linux OS with 1 Public IPV6 address | I6: Number | J6: 5340.5
B7: 3 | C7: S4 Plan: 4 vCPU 24 GB RAM 100 GB HDD 1000 IOPS, 100 GB data transfer / Month, OS: Linux OS with 1 Public IPV6 address | D7: Number | E7: 12118.7 | G7: 3 | H7: S4 Plan: 4 vCPU 24 GB RAM 100 GB HDD 1000 IOPS, 100 GB data transfer / Month, OS: Linux OS with 1 Public IPV6 address | I7: Number | J7: 7279.8
B8: 4 | C8: S5 Plan: 4vCPU 32 GB RAM 100 GB HDD 1000 IOPS, 100 GB data transfer / Month, OS: Linux OS with 1 Public IPV6 address | D8: Number | E8: 14362.7 | G8: 4 | H8: S5 Plan: 4vCPU 32 GB RAM 100 GB HDD 1000 IOPS, 100 GB data transfer / Month, OS: Linux OS with 1 Public IPV6 address | I8: Number | J8: 8142.2
B9: 5 | C9: S5 Plan: 6 vCPU 12 GB RAM 100 GB HDD 1000 IOPS, 100 GB data transfer / Month, OS: Linux OS with 1 Public IPV6 address | D9: Number | E9: 9313.7 | G9: 5 | H9: S5 Plan: 6 vCPU 12 GB RAM 100 GB HDD 1000 IOPS, 100 GB data transfer / Month, OS: Linux OS with 1 Public IPV6 address | I9: Number | J9: 6202.9
B10: 6 | C10: S6 Plan: 6 vCPU 24 GB RAM 100 GB HDD 1000 IOPS, 100 GB data transfer / Month, OS: Linux OS with 1 Public IPV6 address | D10: Number | E10: 12679.7 | G10: 6 | H10: S6 Plan: 6 vCPU 24 GB RAM 100 GB HDD 1000 IOPS, 100 GB data transfer / Month, OS: Linux OS with 1 Public IPV6 address | I10: Number | J10: 7495.4
B11: 7 | C11: S7 Plan: 6 vCPU 32 GB RAM 100 GB HDD 1000 IOPS, 100 GB data transfer / Month, OS: Linux OS with 1 Public IPV6 address | D11: Number | E11: 14923.7 | G11: 7 | H11: S7 Plan: 6 vCPU 32 GB RAM 100 GB HDD 1000 IOPS, 100 GB data transfer / Month, OS: Linux OS with 1 Public IPV6 address | I11: Number | J11: 8356.7
B12: 8 | C12: S10 Plan: 8 vCPU 56 GB RAM 100 GB HDD 1000 IOPS, 100 GB data transfer / Month, OS: Linux OS with 1 Public IPV6 address | D12: Number | E12: 22216.7 | G12: 8 | H12: S10 Plan: 8 vCPU 56 GB RAM 100 GB HDD 1000 IOPS, 100 GB data transfer / Month, OS: Linux OS with 1 Public IPV6 address | I12: Number | J12: 11157.3
B13: 9 | C13: S11 Plan: 8 vCPU 64 GB RAM 100 GB HDD 1000 IOPS, 100 GB data transfer / Month, OS: Linux OS with 1 Public IPV6 address | D13: Number | E13: 24460.7 | G13: 9 | H13: S11 Plan: 8 vCPU 64 GB RAM 100 GB HDD 1000 IOPS, 100 GB data transfer / Month, OS: Linux OS with 1 Public IPV6 address | I13: Number | J13: 12019.7
E14: 0
B15: 1 | C15: M1 Plan: 8 vCPU 128 GB RAM 100 GB HDD 1000 IOPS, 100 GB data transfer / Month, OS: Linux OS with 1 Public IPV6 address | D15: Number | E15: 42413.8 | G15: 1 | H15: M1 Plan: 8 vCPU 128 GB RAM 100 GB HDD 1000 IOPS, 100 GB data transfer / Month, OS: Linux OS with 1 Public IPV6 address | I15: Number | J15: 18913.4
B16: 2 | C16: M2 Plan: 8 vCPU 256 GB RAM 100 GB HDD 1000 IOPS, 100 GB data transfer / Month, OS: Linux OS with 1 Public IPV6 address | D16: Number | E16: 78320 | G16: 2 | H16: M2 Plan: 8 vCPU 256 GB RAM 100 GB HDD 1000 IOPS, 100 GB data transfer / Month, OS: Linux OS with 1 Public IPV6 address | I16: Number | J16: 32701.9
B17: 3 | C17: M3 Plan: 10 vCPU 24 GB RAM 100 GB HDD 1000 IOPS, 100 GB data transfer / Month, OS: Linux OS with 1 Public IPV6 address | D17: Number | E17: 13801.7 | G17: 3 | H17: M3 Plan: 10 vCPU 24 GB RAM 100 GB HDD 1000 IOPS, 100 GB data transfer / Month, OS: Linux OS with 1 Public IPV6 address | I17: Number | J17: 7926.6
B18: 4 | C18: M4 Plan: 10 vCPU 32 GB RAM 100 GB HDD 1000 IOPS, 100 GB data transfer / Month, OS: Linux OS with 1 Public IPV6 address | D18: Number | E18: 16045.7 | G18: 4 | H18: M4 Plan: 10 vCPU 32 GB RAM 100 GB HDD 1000 IOPS, 100 GB data transfer / Month, OS: Linux OS with 1 Public IPV6 address | I18: Number | J18: 8787.9
B19: 5 | C19: M5 Plan: 12 vCPU 12 GB RAM 100 GB HDD 1000 IOPS, 100 GB data transfer / Month, OS: Linux OS with 1 Public IPV6 address | D19: Number | E19: 10996.7 | G19: 5 | H19: M5 Plan: 12 vCPU 12 GB RAM 100 GB HDD 1000 IOPS, 100 GB data transfer / Month, OS: Linux OS with 1 Public IPV6 address | I19: Number | J19: 6848.6
B20: 6 | C20: M6 Plan: 12 vCPU 16 GB RAM 100 GB HDD 1000 IOPS, 100 GB data transfer / Month, OS: Linux OS with 1 Public IPV6 address | D20: Number | E20: 12118.7 | G20: 6 | H20: M6 Plan: 12 vCPU 16 GB RAM 100 GB HDD 1000 IOPS, 100 GB data transfer / Month, OS: Linux OS with 1 Public IPV6 address | I20: Number | J20: 7279.8
B21: 7 | C21: M7 Plan: 12 vCPU 32 GB RAM 100 GB HDD 1000 IOPS, 100 GB data transfer / Month, OS: Linux OS with 1 Public IPV6 address | D21: Number | E21: 16606.7 | G21: 7 | H21: M7 Plan: 12 vCPU 32 GB RAM 100 GB HDD 1000 IOPS, 100 GB data transfer / Month, OS: Linux OS with 1 Public IPV6 address | I21: Number | J21: 9003.5
B22: 8 | C22: M8 Plan: 12 vCPU 48 GB RAM 100 GB HDD 1000 IOPS, 100 GB data transfer / Month, OS: Linux OS with 1 Public IPV6 address | D22: Number | E22: 21094.7 | G22: 8 | H22: M8 Plan: 12 vCPU 48 GB RAM 100 GB HDD 1000 IOPS, 100 GB data transfer / Month, OS: Linux OS with 1 Public IPV6 address | I22: Number | J22: 10727.2
B23: 9 | C23: M9 Plan: 12 vCPU 64 GB RAM 100 GB HDD 1000 IOPS, 100 GB data transfer / Month, OS: Linux OS with 1 Public IPV6 address | D23: Number | E23: 25582.7 | G23: 9 | H23: M9 Plan: 12 vCPU 64 GB RAM 100 GB HDD 1000 IOPS, 100 GB data transfer / Month, OS: Linux OS with 1 Public IPV6 address | I23: Number | J23: 12450.9
B24: 10 | C24: M10 Plan: 12 vCPU 128 GB RAM 100 GB HDD 1000 IOPS, 100 GB data transfer / Month, OS: Linux OS with 1 Public IPV6 address | D24: Number | E24: 43535.8 | G24: 10 | H24: M10 Plan: 12 vCPU 128 GB RAM 100 GB HDD 1000 IOPS, 100 GB data transfer / Month, OS: Linux OS with 1 Public IPV6 address | I24: Number | J24: 19344.6
B25: 11 | C25: M11 Plan: 14 vCPU 28 GB RAM 100 GB HDD 1000 IOPS, 100 GB data transfer / Month, OS: Linux OS with 1 Public IPV6 address | D25: Number | E25: 16045.7 | G25: 11 | H25: M11 Plan: 14 vCPU 28 GB RAM 100 GB HDD 1000 IOPS, 100 GB data transfer / Month, OS: Linux OS with 1 Public IPV6 address | I25: Number | J25: 8787.9
B26: 12 | C26: M12 Plan: 14 vCPU 32 GB RAM 100 GB HDD 1000 IOPS, 100 GB data transfer / Month, OS: Linux OS with 1 Public IPV6 address | D26: Number | E26: 17167.7 | G26: 12 | H26: M12 Plan: 14 vCPU 32 GB RAM 100 GB HDD 1000 IOPS, 100 GB data transfer / Month, OS: Linux OS with 1 Public IPV6 address | I26: Number | J26: 9219.1
... B28: 14 | C28: M14 Plan: 14 vCPU 128 GB RAM 100 GB HDD 1000 IOPS, 100 GB data transfer / Month, OS: Linux OS with 1 Public IPV6 address | D28: Number | E28: 44096.8 | G28: 14 | H28: M14 Plan: 14 vCPU 128 GB RAM 100 GB HDD 1000 IOPS, 100 GB data transfer / Month, OS: Linux OS with 1 Public IPV6 address | I28: Number | J28: 19560.2
E29: 0
B30: 1 | C30: L1 Plan: 16 vCPU 16 GB RAM 100 GB HDD 1000 IOPS, 100 GB data transfer / Month, OS: Linux OS with 1 Public IPV6 address | D30: Number | E30: 13240.7 | G30: 1 | H30: L1 Plan: 16 vCPU 16 GB RAM 100 GB HDD 1000 IOPS, 100 GB data transfer / Month, OS: Linux OS with 1 Public IPV6 address | I30: Number | J30: 7711
B31: 2 | C31: L2 Plan: 16 vCPU 32 GB RAM 100 GB HDD 1000 IOPS, 100 GB data transfer / Month, OS: Linux OS with 1 Public IPV6 address | D31: Number | E31: 17728.7 | G31: 2 | H31: L2 Plan: 16 vCPU 32 GB RAM 100 GB HDD 1000 IOPS, 100 GB data transfer / Month, OS: Linux OS with 1 Public IPV6 address | I31: Number | J31: 9434.7
B32: 3 | C32: L3 Plan: 16 vCPU 128 GB RAM 100 GB HDD 1000 IOPS, 100 GB data transfer / Month, OS: Linux OS with 1 Public IPV6 address | D32: Number | E32: 44657.8 | G32: 3 | H32: L3 Plan: 16 vCPU 128 GB RAM 100 GB HDD 1000 IOPS, 100 GB data transfer / Month, OS: Linux OS with 1 Public IPV6 address | I32: Number | J32: 19775.8
B33: 4 | C33: L4 Plan: 16 vCPU 256 GB RAM 100 GB HDD 1000 IOPS, 100 GB data transfer / Month, OS: Linux OS with 1 Public IPV6 address | D33: Number | E33: 80564 | G33: 4 | H33: L4 Plan: 16 vCPU 256 GB RAM 100 GB HDD 1000 IOPS, 100 GB data transfer / Month, OS: Linux OS with 1 Public IPV6 address | I33: Number | J33: 33563.2
B34: 5 | C34: L5 Plan: 32 vCPU 32 GB RAM 100 GB HDD 1000 IOPS, 100 GB data transfer / Month, OS: Linux OS with 1 Public IPV6 address | D34: Number | E34: 22216.7 | G34: 5 | H34: L5 Plan: 32 vCPU 32 GB RAM 100 GB HDD 1000 IOPS, 100 GB data transfer / Month, OS: Linux OS with 1 Public IPV6 address | I34: Number | J34: 11157.3
B35: 6 | C35: L6 Plan: 32 vCPU 64 GB RAM 100 GB HDD 1000 IOPS, 100 GB data transfer / Month, OS: Linux OS with 1 Public IPV6 address | D35: Number | E35: 31193.8 | G35: 6 | H35: L6 Plan: 32 vCPU 64 GB RAM 100 GB HDD 1000 IOPS, 100 GB data transfer / Month, OS: Linux OS with 1 Public IPV6 address | I35: Number | J35: 14604.7
B36: 7 | C36: L7 Plan: 32 vCPU 128 GB RAM 100 GB HDD 1000 IOPS, 100 GB data transfer / Month, OS: Linux OS with 1 Public IPV6 address | D36: Number | E36: 49146.9 | G36: 7 | H36: L7 Plan: 32 vCPU 128 GB RAM 100 GB HDD 1000 IOPS, 100 GB data transfer / Month, OS: Linux OS with 1 Public IPV6 address | I36: Number | J36: 21498.4
B38: 1 | C38: XL 1 Plan: 14 vCPU 128 GB RAM 100 GB HDD 1000 IOPS, 100 GB data transfer / Month, OS: Linux OS with 1 Public IPV6 address | D38: Number | E38: 44096.8 | G38: 1 | H38: XL 1 Plan: 14 vCPU 128 GB RAM 100 GB HDD 1000 IOPS, 100 GB data transfer / Month, OS: Linux OS with 1 Public IPV6 address | I38: Number | J38: 19560.2
B39: 2 | C39: XL 2 Plan: 16 vCPU 256 GB RAM 100 GB HDD 1000 IOPS, 100 GB data transfer / Month, OS: Linux OS with 1 Public IPV6 address | D39: Number | E39: 80564 | G39: 2 | H39: XL 2 Plan: 16 vCPU 256 GB RAM 100 GB HDD 1000 IOPS, 100 GB data transfer / Month, OS: Linux OS with 1 Public IPV6 address | I39: Number | J39: 33563.2
B40: 3 | C40: XL 3 Plan: 16 vCPU 512 GB RAM 100 GB HDD 1000 IOPS, 100 GB data transfer / Month, OS: Linux OS with 1 Public IPV6 address | D40: Number | E40: 152376.4 | G40: 3 | H40: XL 3 Plan: 16 vCPU 512 GB RAM 100 GB HDD 1000 IOPS, 100 GB data transfer / Month, OS: Linux OS with 1 Public IPV6 address | I40: Number | J40: 61139.1
B41: 4 | C41: XL 4 Plan: 32 vCPU 256 GB RAM 100 GB HDD 1000 IOPS, 100 GB data transfer / Month, OS: Linux OS with 1 Public IPV6 address | D41: Number | E41: 85053.1 | G41: 4 | H41: XL 4 Plan: 32 vCPU 256 GB RAM 100 GB HDD 1000 IOPS, 100 GB data transfer / Month, OS: Linux OS with 1 Public IPV6 address | I41: Number | J41: 35286.9
B42: 5 | C42: XL 5 Plan: 32 vCPU 512 GB RAM 100 GB HDD 1000 IOPS, 100 GB data transfer / Month, OS: Linux OS with 1 Public IPV6 address | D42: Number | E42: 156865.5 | G42: 5 | H42: XL 5 Plan: 32 vCPU 512 GB RAM 100 GB HDD 1000 IOPS, 100 GB data transfer / Month, OS: Linux OS with 1 Public IPV6 address | I42: Number | J42: 62862.8
...

Sheet SOC Services
A2: Sr. No | B2: Service | C2: Cost for Additional Components/Service | D2: Unit of Measurement | E2: Total Price/Month (INR) | F2: One Time Cost (INR- Lakh) | G2: Additional Information
B3: Main Product (Main SKU) | C3: Additional Service (Sub-SKU)
A4: 1 | B4: Fully Managed SOC as Service- Eagle Eye Services | D4: Per Log Source | E4: 3594.8 | F4: 6.51 | G4: Costing Considering EPS of upto 500 and Log retention of upto 6 Months and Internet Bandwith at Service Provider end of upto 10 Mbps. OTC Will be for the complete project and may vary if additional Scope is involved, no Onsite Support is considered. The mentioned costs does not consider any specific SIEM that is offered through ESDS and the appropriate SIEM will be used at ESDS end.
A5: 1a | C5: Storage Per GB | D5: Per GB | E5: 16.5 | F5: 0
A6: 1b | C6: Service Provider Internet Bandwith per Mbps | D6: Per Mbps | E6: 477.4 | F6: 0
B7: Main Product (Main SKU) | C7: Additional Service (Sub-SKU)
A8: 2 | B8: Managed SOC Services for SIEM On-Site with all Resouces at Service Provider Location and no named resource for the Project | D8: SOC Monitoring only from SP Location | E8: 224413.2 | F8: 5.1 | G8: The Cost provided is for upto SOC Monitoring and reporting for upto 150 devices monitored through the Customer SIEM at Customer Location. Integration with ESDS Ticketing tool is included in the pricing.
A9: 2a | C9: Each Named L1 SOC Engineer for the Project at Service Provider Location- Shared | D9: Per Engineer | E9: 134647.7 | F9: 0
A10: 2b | C10: Each Named L2 SOC Engineer for the Project at Service Provider Location- Shared | D10: Per Engineer | E10: 201972.1 | F10: 0
A11: 2c | C11: Each Named L3 engineer for the Project at Service Provider Location- Shared | D11: Per Engineer | E11: 403944.2 | F11: 0
B12: Main Product (Main SKU) | C12: Additional Service (Sub-SKU)
A13: 3 | B13: Managed SOC Services for SIEM On-Site with all Resources at Client Location. | C13: The Below Manpower is an essential part of this Service and cannot be taken Standalone | D13: Project On Boarding | E13: 0 | F13: 10.2 | G13: No Capex or investment on Equipments/Devices are considered here. OTC considered is for initial Transitionining and on boarding
C14: Each Dedicated L1 SOC Engineer onsite | D14: Per Engineer | E14: 224413.2 | F14: 0 | G14: Standard SOC Monitoring Funcionality would be renedered through these engineers. Additional Functionality like remediation and consulting would need more specialised resources and cost will change accordingly
C15: Each Dedicated L2 SOC Engineer onsite | D15: Per Engineer | E15: 359062 | F15: 0
C16: Each Dedicated L3 SOC Engineer onsite | D16: Per Engineer | E16: 561034.1 | F16: 0
C17: Team Lead SOC Onsite | D17: One Team Lead | E17: 617137.4 | F17: 0
B18: Main Product (Main SKU) | C18: Additional Service (Sub-SKU)
A19: 4 | B19: Brand Reputation Risk Monitoring with Take Down Services | G19: Pricing will need to be arrived at based on coverage and scope which may vary for various departments
A20: 5 | B20: Cyber Crime and Dark Web Intelligence | G20: Pricing will need to be arrived at based on coverage and scope which may vary for various departments
A21: 6 | B21: Managed EDR as a Service | D21: Per End Point | E21: 2468.4 | F21: 10.2 | G21: Will be offered from ESDS SOC with agents deployed at customers endpoints. The costs are for upto 500 endpoints, retention period of 1 month, upto 1000eps and no onsite support is considered.
A22: 7 | B22: Managed DLP as a Service | D22: Per End Point | E22: 2244 | F22: 10.2 | G22: Will be offered from ESDS SOC with agents deployed at customers endpoints. The costs are for upto 500 endpoints, retention period of 1 month, upto 1000eps and no onsite support is considered.
A23: 8 | B23: Security Assessment Services (Security Insight Services) | D23: Project Based | E23: 0 | G23: The Pricing will be based on scope and depth of the Assessment.
A24: 9 | B24: VAPT Services | D24: Per IP | E24: 6732 | G24: The Pricing is based on minimum order of 250 Ips
